Workbook

Sheet Analiza_KPA
J1: =22*(7822/365) -> 471.46301
E2: 02.09.1997 | J2: 22.01.2002
B3: No. | C3: DESCRIPTION / PERIOD | D3: 1996 | E3: 1997 | F3: 1998 | G3: 1999 | H3: 2000 | I3: 2001 | J3: 2002 | K3: 2003 | L3: 1996-2003 | M3: 2004 | N3: 2005 | O3: 2006 | P3: 2007 | Q3: 2008 | R3: 2009 | S3: 2010 | T3: 2011 | U3: 2012 | V3: 2013 | W3: 2014 | X3: 2015 | Y3: 2016 | Z3: TOTALI | AA3: VETTING
B4: I | C4: INCOME | D4: =SUM(D5:D10) -> 60154 | E4: =SUM(E5:E10) -> 231024 | F4: =SUM(F5:F10) -> 360525 | G4: =SUM(G5:G10) -> 461249 | H4: =SUM(H5:H10) -> 603437 | I4: =SUM(I5:I10) -> 636075.5 | J4: =SUM(J5:J10) -> 608853.5 | K4: =SUM(K5:K10) -> 765140 | L4: =SUM(L5:L10) -> 3726458 | M4: =SUM(M5:M11) -> 933625 | N4: =SUM(N5:N10) -> 1145795 | O4: =SUM(O5:O10) -> 1093156 | P4: =SUM(P5:P10) -> 1029704 | Q4: =SUM(Q5:Q10) -> 1623856 | R4: =SUM(R5:R10) -> 1349735 | S4: =SUM(S5:S10) -> 1389475 | T4: =SUM(T5:T10) -> 1519983 | U4: =SUM(U5:U10) -> 1568737 | ... Z4: =SUM(Z5:Z10) -> 27337579 | AA4: 175673
B5: 1 | C5: Income of Assessee | D5: ='Te Ardhurat '!D4 -> 60154 | E5: ='Te Ardhurat '!E4 -> 231024 | F5: ='Te Ardhurat '!F4 -> 360525 | G5: ='Te Ardhurat '!G4 -> 390615 | H5: ='Te Ardhurat '!H4 -> 442564 | I5: ='Te Ardhurat '!I4 -> 446705 | J5: ='Te Ardhurat '!J4 -> 414633 | K5: ='Te Ardhurat '!K4 -> 473716 | L5: =SUM(D5:K5) -> 2819936 | M5: ='Te Ardhurat '!L4+'Te Ardhurat '!L5 -> 606194 | N5: ='Te Ardhurat '!M5 -> 818245 | O5: ='Te Ardhurat '!N5 -> 815652 | P5: ='Te Ardhurat '!O5+'Te Ardhurat '!O6 -> 841418 | Q5: ='Te Ardhurat '!P6 -> 905278 | R5: ='Te Ardhurat '!Q6 -> 851469 | S5: ='Te Ardhurat '!R6+'Te Ardhurat '!R7 -> 814286 | T5: ='Te Ardhurat '!S7 -> 942368 | U5: ='Te Ardhurat '!T7 -> 983776 | V5: ='Te Ardhurat '!U7 -> 917794 | W5: ='Te Ardhurat '!V7 -> 1091512 | X5: ='Te Ardhurat '!W7 -> 1123493 | Y5: ='Te Ardhurat '!X7 -> 1170841 | Z5: =SUM(M5:Y5)+K5 -> 12356042 | AA5: 99845
B6: 2 | C6: Income of Spouse | D6: 0 | E6: 0 | F6: 0 | G6: ='Te Ardhurat '!G20+'Te Ardhurat '!G21 -> 70634 | H6: ='Te Ardhurat '!H20+'Te Ardhurat '!H21 -> 160873 | I6: ='Te Ardhurat '!I20+'Te Ardhurat '!I21 -> 189370.5 | J6: ='Te Ardhurat '!J20+'Te Ardhurat '!J21 -> 194220.5 | K6: ='Te Ardhurat '!K20+'Te Ardhurat '!K21 -> 291424 | L6: =SUM(D6:K6) -> 906522 | M6: ='Te Ardhurat '!L20 -> 327431 | N6: ='Te Ardhurat '!M20 -> 327550 | O6: ='Te Ardhurat '!N20 -> 277504 | P6: ='Te Ardhurat '!O22+'Te Ardhurat '!O23 -> 188286 | Q6: ='Te Ardhurat '!P22+'Te Ardhurat '!P23 -> 318578 | R6: ='Te Ardhurat '!Q22+'Te Ardhurat '!Q23 -> 498266 | S6: ='Te Ardhurat '!R22+'Te Ardhurat '!R23 -> 575189 | T6: ='Te Ardhurat '!S22+'Te Ardhurat '!S23 -> 577615 | U6: ='Te Ardhurat '!T22+'Te Ardhurat '!T23 -> 584961 | V6: ='Te Ardhurat '!U22+'Te Ardhurat '!U23 -> 596778 | W6: ='Te Ardhurat '!V22+'Te Ardhurat '!V23 -> 749732 | ... Y6: ='Te Ardhurat '!X22+'Te Ardhurat '!X23 -> 904419 | Z6: =SUM(M6:Y6)+K6 -> 7034347 | AA6: 75828
B7: 3 | C7: Sale of "Mercedes Benz"_09.09.2008 | D7: 0 | E7: 0 | F7: 0 | G7: 0 | H7: 0 | I7: 0 | J7: 0 | K7: 0 | L7: 0 | M7: 0 | N7: 0 | O7: 0 | P7: 0 | Q7: 400000 | R7: 0 | S7: 0 | T7: 0 | U7: 0 | V7: 0 | W7: 0 | X7: 0 | Y7: 0 | Z7: =SUM(M7:Y7)+K7 -> 400000 | AA7: 0
B8: 4 | C8: Down payment for sale of house in K.Kamëz_01.10.2014 | D8: 0 | E8: 0 | F8: 0 | G8: 0 | H8: 0 | I8: 0 | J8: 0 | K8: 0 | L8: 0 | M8: 0 | N8: 0 | O8: 0 | P8: 0 | Q8: 0 | R8: 0 | S8: 0 | T8: 0 | U8: 0 | V8: 0 | W8: =20000*139.87 -> 2797400 | X8: =30000*140.84 -> 4225200 | Y8: 0 | Z8: =SUM(M8:Y8)+K8 -> 7022600
B9: 5 | C9: Sale of "Mercedes Benz"15.03.2016 | D9: 0 | E9: 0 | F9: 0 | G9: 0 | H9: 0 | I9: 0 | J9: 0 | K9: 0 | L9: 0 | M9: 0 | N9: 0 | O9: 0 | P9: 0 | Q9: 0 | R9: 0 | S9: 0 | T9: 0 | U9: 0 | V9: 0 | W9: 0 | X9: 0 | Y9: =3800*138.05 -> 524590 | Z9: =SUM(M9:Y9)+K9 -> 524590 | AA9: 0
B10: 6 | C10: Sale of house in K.Kamëz cont.16.06.2017 | D10: 0 | E10: 0 | F10: 0 | G10: 0 | H10: 0 | I10: 0 | J10: 0 | K10: 0 | L10: 0 | M10: 0 | N10: 0 | O10: 0 | P10: 0 | Q10: 0 | R10: 0 | S10: 0 | T10: 0 | U10: 0 | V10: 0 | W10: 0 | X10: 0 | Y10: 0 | Z10: =SUM(M10:Y10)+K10 -> 0
B11: 7 | C11: Settled from use of agr. land | D11: 0 | E11: 0 | F11: 0 | G11: 0 | H11: 0 | I11: 0 | J11: 0 | K11: 0 | L11: 0 | M11: 0 | N11: 300000 | O11: 100000 | P11: 200000 | Q11: 370000 | R11: 350000 | S11: 470000 | T11: 530000 | U11: 670000 | V11: 540000 | W11: 450000 | X11: 240000 | Y11: 200000 | Z11: =SUM(M11:Y11)+K11 -> 4420000
B13: II | C13: EXPENDITURE | D13: =SUM(D14:D22) -> 39701.64 | E13: =SUM(E14:E22) -> 152475.84 | F13: =SUM(F14:F22) -> 237946.5 | G13: =SUM(G14:G22) -> 257805.9 | H13: =SUM(H14:H22) -> 216000 | I13: =SUM(I14:I22) -> 216000 | J13: =SUM(J14:J22) -> 374984.54 | K13: =SUM(K14:K22) -> 375456 | ... Z13: =SUM(Z14:Z22) -> 11980242 | AA13: 113918.35
B14: 1 | C14: Living expenses | D14: =D5*66% -> 39701.64 | E14: =E5*66% -> 152475.84 | F14: =F5*66% -> 237946.5 | G14: =G5*66% -> 257805.9 | H14: =108000*2 -> 216000 | I14: =H14 -> 216000 | J14: =93864*4-J1 -> 374984.54 | K14: 375456 | L14: =SUM(D14:K14) -> 1870370.4 | M14: 375856 | N14: 438228 | O14: 438228 | P14: 546480 | Q14: 546480 | R14: =546480 -> 546480 | S14: =546480 -> 546480 | T14: =546480 -> 546480 | U14: 564096 | V14: 564096 | W14: 879992 | X14: 897104 | Y14: 940368 | Z14: =SUM(M14:Y14)+K14 -> 8205824 | AA14: 79351.351
B15: 2 | C15: Travel expenses TIMS | D15: 0 | E15: 0 | F15: 0 | G15: 0 | H15: 0 | I15: 0 | J15: 0 | K15: 0 | L15: 0 | M15: 0 | N15: 0 | O15: 0 | P15: 0 | Q15: 3695.475 | R15: 0 | S15: 0 | T15: =TIMS!F6 -> 338835 | U15: 0 | V15: =TIMS!G6 -> 0 | W15: =TIMS!I6 -> 140110 | X15: =TIMS!J6 -> 37165.5 | Y15: =TIMS!K6 -> 31054 | Z15: =SUM(M15:Y15)+K15 -> 550859.97 | AA15: 7977 | AC15: 2196
B16: 3 | C16: Legalization expenses 3-storey house 01.07.2015 | D16: 0 | E16: 0 | F16: 0 | G16: 0 | H16: 0 | I16: 0 | J16: 0 | K16: 0 | L16: 0 | M16: 0 | N16: 0 | O16: 0 | P16: 0 | Q16: 0 | R16: 0 | S16: 0 | T16: 0 | U16: 0 | V16: 0 | W16: 0 | X16: =(500000*0.1)+360000 -> 410000 | Y16: 0 | Z16: =SUM(M16:Y16)+K16 -> 410000
B17: 4 | C17: Exp. on local tax on agr. land | D17: 0 | E17: 0 | F17: 0 | G17: 0 | H17: 0 | I17: 0 | J17: 0 | K17: 0 | L17: 0 | M17: 0 | N17: 0 | O17: 0 | P17: 732 | Q17: 732 | R17: 732 | S17: 1350 | T17: 1350 | U17: 1227 | V17: 1520.5 | W17: 1520.5 | X17: 1229 | Y17: 1651.24 | Z17: =SUM(M17:Y17)+K17 -> 12044.24
B18: 5 | C18: Education expenses_Enea Sharra | D18: 0 | E18: 0 | F18: 0 | G18: 0 | H18: 0 | I18: 0 | J18: 0 | K18: 0 | L18: 0 | M18: 0 | N18: 0 | O18: 0 | P18: 0 | Q18: 0 | R18: 0 | S18: 0 | T18: 0 | U18: 0 | V18: 0 | W18: 0 | X18: 16000 | Y18: 40000 | Z18: =SUM(M18:Y18)+K18 -> 56000
B19: 6 | C19: Education expenses_Ersa Sharra_"F.Konica" | D19: 0 | E19: 0 | F19: 0 | G19: 0 | H19: 0 | I19: 0 | J19: 0 | K19: 0 | L19: 0 | M19: 0 | N19: 0 | O19: 0 | P19: 0 | Q19: 0 | R19: 0 | S19: 0 | T19: 0 | U19: 0 | V19: 95903.64 | W19: 244632.06 | X19: 247770 | Y19: 254307.6 | Z19: =SUM(M19:Y19)+K19 -> 842613.3 | AA19: 26590
B20: 7 | C20: Education expenses Ersa Sharra_"Elitë" | D20: 0 | E20: 0 | F20: 0 | G20: 0 | H20: 0 | I20: 0 | J20: 0 | K20: 0 | L20: 0 | M20: 0 | N20: 0 | O20: 0 | P20: 0 | Q20: 0 | R20: 0 | S20: 0 | T20: 0 | U20: 0 | V20: 0 | W20: 0 | X20: 0 | Y20: 0 | Z20: =SUM(M20:Y20)+K20 -> 0
B21: 8 | C21: Furnishing expenses | D21: 0 | E21: 0 | F21: 0 | G21: 0 | H21: 0 | I21: 0 | J21: 0 | K21: 0 | L21: 0 | M21: 0 | N21: 0 | O21: 0 | P21: 0 | Q21: 0 | R21: 0 | S21: 0 | T21: 0 | U21: 0 | V21: 0 | W21: 186813.33 | X21: 186813.33 | Y21: 186813.33 | Z21: =SUM(M21:Y21)+K21 -> 560440
B22: 9 | C22: Exp.on loan interests+commissions NBG | D22: 0 | E22: 0 | F22: 0 | G22: 0 | H22: 0 | I22: 0 | J22: 0 | K22: 0 | L22: 0 | M22: 0 | N22: 0 | O22: 0 | P22: 0 | Q22: =32*121.67+'Kredi ne NBG '!D38*KK!R4 -> 216571.72 | R22: ='Kredi ne NBG '!F49*KK!S4 -> 293827.74 | S22: ='Kredi ne NBG '!H45*KK!T4 -> 266262.57 | T22: ='Kredi ne NBG '!J61*KK!U4 -> 232151.76 | U22: ='Kredi ne NBG '!L61*KK!V4 -> 159912.33 | V22: ='Kredi ne NBG '!N69*KK!W4 -> 173734.21 | W22: 0 | X22: 0 | Y22: 0 | Z22: =SUM(M22:Y22)+K22 -> 1342460.3
B24: III | C24: ASSETS | D24: =SUM(D25:D31) -> 0 | E24: =SUM(E25:E31) -> 0 | F24: =SUM(F25:F31) -> 0 | G24: =SUM(G25:G31) -> 0 | H24: =SUM(H25:H31) -> 0 | I24: =SUM(I25:I31) -> 0 | J24: =SUM(J25:J31) -> 0 | K24: =SUM(K25:K31) -> 267300 | ... AA24: =SUM(AA25:AA31) -> 9673
B25: 1 | C25: House_ 134.5 m2 | D25: 0 | E25: 0 | F25: 0 | G25: 0 | H25: 0 | I25: 0 | J25: 0 | K25: 0 | L25: =SUM(D25:K25) -> 0 | M25: 0 | N25: 0 | O25: 0 | P25: 0 | Q25: 0 | R25: 0 | S25: 0 | T25: 0 | U25: 0 | V25: 0 | W25: 0 | X25: 0 | Y25: 0 | Z25: =SUM(M25:Y25)+K25 -> 0
B26: 2 | C26: "Mercedes Benz" 1988_2003 | D26: 0 | E26: 0 | F26: 0 | G26: 0 | H26: 0 | I26: 0 | J26: 0 | K26: =2000*133.65 -> 267300 | L26: =SUM(D26:K26) -> 267300 | M26: 0 | N26: 0 | O26: 0 | P26: 0 | Q26: 0 | R26: 0 | S26: 0 | T26: 0 | U26: 0 | V26: 0 | W26: 0 | X26: 0 | Y26: 0 | Z26: =SUM(M26:Y26)+K26 -> 267300
B27: 3 | C27: Apartment . 128.1 m2_23.06.2008 | D27: 0 | E27: 0 | F27: 0 | G27: 0 | H27: 0 | I27: 0 | J27: 0 | K27: 0 | L27: =SUM(D27:K27) -> 0 | M27: 0 | N27: 0 | O27: 0 | P27: 0 | Q27: =94830*121.99 -> 11568312 | R27: 0 | S27: 0 | T27: 0 | U27: 0 | V27: 0 | W27: 0 | X27: 0 | Y27: 0 | Z27: =SUM(M27:Y27)+K27 -> 11568312
B28: 4 | C28: "Daimler Chrysler"_14.11.2008 | D28: 0 | E28: 0 | F28: 0 | G28: 0 | H28: 0 | I28: 0 | J28: 0 | K28: 0 | L28: =SUM(D28:K28) -> 0 | M28: 0 | N28: 0 | O28: 0 | P28: 0 | Q28: =5500*123.25 -> 677875 | R28: 0 | S28: 0 | T28: 0 | U28: 0 | V28: 0 | W28: 0 | X28: 0 | Y28: 0 | Z28: =SUM(M28:Y28)+K28 -> 677875
B29: 5 | C29: Garage 45 m2_13.04.2013 | D29: 0 | E29: 0 | F29: 0 | G29: 0 | H29: 0 | I29: 0 | J29: 0 | K29: 0 | L29: =SUM(D29:K29) -> 0 | M29: 0 | N29: 0 | O29: 0 | P29: 0 | Q29: 0 | R29: 0 | S29: 0 | T29: 0 | U29: 0 | V29: =11000*140.21 -> 1542310 | W29: 0 | X29: 0 | Y29: 0 | Z29: =SUM(M29:Y29)+K29 -> 1542310
B30: 6 | C30: "Mercedes Benz"_02.03.2017 | D30: 0 | E30: 0 | F30: 0 | G30: 0 | H30: 0 | I30: 0 | J30: 0 | K30: 0 | L30: =SUM(D30:K30) -> 0 | M30: 0 | N30: 0 | O30: 0 | P30: 0 | Q30: 0 | R30: 0 | S30: 0 | T30: 0 | U30: 0 | V30: 0 | W30: 0 | X30: 0 | Y30: 0 | Z30: =SUM(M30:Y30)+K30 -> 0
B31: 7 | C31: Change of liquidity | D31: 0 | E31: 0 | F31: 0 | G31: 0 | H31: 0 | I31: 0 | J31: 0 | K31: 0 | L31: 0 | M31: 0 | N31: =N32-M32 -> 604815.44 | O31: =O32-N32 -> 863578.06 | P31: =+' Likujditete'!S58 -> 339106.54 | Q31: =+' Likujditete'!T58 -> 395498.02 | R31: =R32-Q32 -> -1543902.5 | S31: =S32-R32 -> 1270.44 | T31: =T32-S32 -> 413557.02 | U31: =U32-T32 -> 138927 | V31: =V32-U32 -> 1093559.8 | W31: =W32-V32 -> 198214.83 | X31: =X32-W32 -> 64549.13 | Y31: =Y32-X32 -> 668773.15 | Z31: =SUM(M31:Y31)+K31 -> 3237946.9 | AA31: =+' Likujditete'!AD58 -> 9673
B32: 7/a | C32: Total liquidity | D32: 0 | E32: 0 | F32: 0 | G32: 0 | H32: 0 | I32: 0 | J32: 0 | K32: 0 | L32: 0 | M32: 0 | N32: =SUM(N33:N34) -> 604815.44 | O32: =SUM(O33:O34) -> 1468393.5 | P32: =SUM(P33:P34) -> 1807500 | Q32: =SUM(Q33:Q34) -> 2202998.1 | R32: =SUM(R33:R34) -> 659095.6 | S32: =SUM(S33:S34) -> 660366.04 | T32: =SUM(T33:T34) -> 1073923.1 | U32: =SUM(U33:U34) -> 1212850.1 | ... Z32: =SUM(Z33:Z34) -> 20308097
B33: 7/b | C33: Liquidity in bank | D33: 0 | E33: 0 | F33: 0 | G33: 0 | H33: 0 | I33: 0 | J33: 0 | K33: 0 | L33: =SUM(D33:K33) -> 0 | M33: =+' Likujditete'!P57 -> 0 | N33: =' Likujditete'!Q53 -> 4815.44 | O33: =' Likujditete'!R53 -> 268393.5 | P33: =' Likujditete'!S53 -> 57500.04 | Q33: =' Likujditete'!T53 -> 52998.06 | R33: =' Likujditete'!U53 -> 9095.6 | S33: =' Likujditete'!V53 -> 48670.04 | T33: =' Likujditete'!W53 -> 62227.06 | U33: =' Likujditete'!X53 -> 61154.06 | V33: =+' Likujditete'!Y57 -> 1154713.8 | W33: =' Likujditete'!Z53 -> 546609.66 | X33: =' Likujditete'!AA53 -> 611158.79 | Y33: =' Likujditete'!AB53 -> 1221931.9 | Z33: =SUM(M33:Y33)+K33 -> 4099268 | AA33: =+' Likujditete'!AD57 -> 1287604.9
B34: 7/c | C34: Cash | D34: 0 | E34: 0 | F34: 0 | G34: 0 | H34: 0 | I34: 0 | J34: 0 | K34: 0 | L34: =SUM(D34:K34) -> 0 | M34: =+' Likujditete'!P54 -> 0 | N34: =+' Likujditete'!Q56 -> 600000 | O34: =N34+600000 -> 1200000 | P34: =O34+550000 -> 1750000 | Q34: =P34+400000 -> 2150000 | R34: =Q34-2000000+500000 -> 650000 | S34: =R34+800000-838304 -> 611696 | T34: =S34+400000 -> 1011696 | U34: =T34+140000 -> 1151696 | V34: =+' Likujditete'!Y56 -> 1151696 | W34: =V34+400000+2900*KK!X4 -> 1958015 | X34: =W34 -> 1958015 | Y34: =X34+58000 -> 2016015 | Z34: =SUM(M34:Y34)+K34 -> 16208829 | AA34: =+' Likujditete'!AD54 -> 0
B36: IV | C36: LIABILITES | D36: =SUM(D37:D45) -> 0 | E36: =SUM(E37:E45) -> 0 | F36: =SUM(F37:F45) -> 0 | G36: =SUM(G37:G45) -> 0 | H36: =SUM(H37:H45) -> 0 | I36: =SUM(I37:I45) -> 0 | J36: =SUM(J37:J45) -> 0 | K36: =SUM(K37:K45) -> 0 | ... AA36: =SUM(AA37:AA45) -> 0
B37: 1 | C37: Loan at NBG _ EUR 46.000_01.08.2008 | D37: 0 | E37: 0 | F37: 0 | G37: 0 | H37: 0 | I37: 0 | J37: 0 | K37: 0 | L37: 0 | M37: 0 | N37: 0 | O37: 0 | P37: 0 | Q37: =46000*121.67 -> 5596820 | R37: 0 | S37: 0 | T37: 0 | U37: 0 | V37: 0 | W37: 0 | X37: 0 | Y37: 0 | Z37: =SUM(M37:Y37)+K37 -> 5596820
B38: 2 | C38: Loan repayment to NBG | D38: 0 | E38: 0 | F38: 0 | G38: 0 | H38: 0 | I38: 0 | J38: 0 | K38: 0 | L38: 0 | M38: 0 | N38: 0 | O38: 0 | P38: 0 | Q38: =-601.09*KK!R4 -> -74043.769 | R38: =-16196.62*KK!S4 -> -2221690.4 | S38: =-4020.03*KK!T4 -> -558020.36 | T38: =-5897.49*KK!U4 -> -815622.87 | U38: =-3475.15*KK!V4 -> -485547.96 | V38: =-668.98*KK!W4 -> -93797.686 | W38: =-'Kredi ne NBG '!O56*KK!X4 -> -2250252.1 | X38: 0 | Y38: 0 | Z38: =SUM(M38:Y38)+K38 -> -6498975.1
B39: 3 | C39: Liability to "KDK" ShPK company | D39: 0 | E39: 0 | F39: 0 | G39: 0 | H39: 0 | I39: 0 | J39: 0 | K39: 0 | L39: 0 | M39: 0 | N39: 0 | O39: 0 | P39: 0 | Q39: =Q27 -> 11568312 | R39: 0 | S39: 0 | T39: 0 | U39: 0 | V39: 0 | W39: 0 | X39: 0 | Y39: 0 | Z39: =SUM(M39:Y39)+K39 -> 11568312
B40: 4 | C40: Liability paid to "KDK" ShPK | D40: 0 | E40: 0 | F40: 0 | G40: 0 | H40: 0 | I40: 0 | J40: 0 | K40: 0 | L40: 0 | M40: 0 | N40: 0 | O40: 0 | P40: 0 | Q40: =-45968*121.67 -> -5592926.6 | R40: 0 | S40: 0 | T40: 0 | U40: =-5000*139.72 -> -698600 | V40: =-40000 -> -40000 | W40: 0 | X40: =-(230*138.33+24400*140.84+5000*137.39) -> -4155261.9 | Z40: =SUM(M40:Y40)+K40 -> -10486788 | AA40: 0
B41: 5 | C41: Loan from the father _ EUR 4.000 _2013 | D41: 0 | E41: 0 | F41: 0 | G41: 0 | H41: 0 | I41: 0 | J41: 0 | K41: 0 | L41: 0 | M41: 0 | N41: 0 | O41: 0 | P41: 0 | Q41: 0 | R41: 0 | S41: 0 | T41: 0 | U41: 0 | V41: 0 | W41: 0 | X41: 0 | Y41: 0 | Z41: =SUM(M41:Y41)+K41 -> 0
B42: 6 | C42: Loan from the mother _ EUR 2.000_2017 | D42: 0 | E42: 0 | F42: 0 | G42: 0 | H42: 0 | I42: 0 | J42: 0 | K42: 0 | L42: 0 | M42: 0 | N42: 0 | O42: 0 | P42: 0 | Q42: 0 | R42: 0 | S42: 0 | T42: 0 | U42: 0 | V42: 0 | W42: 0 | X42: 0 | Y42: 0 | Z42: =SUM(M42:Y42)+K42 -> 0
B43: 7 | C43: Repaid loan to the mother | D43: 0 | E43: 0 | F43: 0 | G43: 0 | H43: 0 | I43: 0 | J43: 0 | K43: 0 | L43: 0 | M43: 0 | N43: 0 | O43: 0 | P43: 0 | Q43: 0 | R43: 0 | S43: 0 | T43: 0 | U43: 0 | V43: 0 | W43: 0 | X43: 0 | Y43: 0 | Z43: =SUM(M43:Y43)+K43 -> 0
...

Sheet 05.10.2007
C2: Analiza finanaciare e S.R. për blerjen e pas. 56.5 m2
B3: Nr. | C3: PASURIA/PERIUDHA | D3: 2006 | E3: 05.10.2007
B5: I | C5: TË ARDHURA | E5: =SUM(E6:E7) -> 786928.5
B6: 1 | C6: Të ardh.S.R._pagat | E6: =[1]sp_NRP_Balance!$M$116 -> 677095
B7: 2 | C7: Të ardh.B.S.R._pagat | E7: ='Te Ardhurat '!O25/12*7 -> 109833.5
B9: II | C9: SHPENZIME | E9: =SUM(E10:E16) -> 550592
B10: 1 | C10: Shpenz.jetike | E10: =943872/12*7 -> 550592
B11: 2 | C11: Shpenz.shkoll.Enea Sharra
B12: 3 | C12: Shpenz.shkoll.Ersa Sharra_"F.Konica"
B13: 4 | C13: Shpenz.udhët._TIMS
B14: 5 | C14: Shpenz.mobilimi
B15: 6 | C15: Shpenz.legal.godinës tre kate K.K.
B16: 7 | C16: Shpenz,taksa vendore_tokë bujq.
B18: III | C18: PASURI | E18: =SUM(E19:E20) -> 7179284.3
B19: 1 | C19: Ap.56.5 m2 rr.T.Tashko | E19: ='KPA_ndërt.2 kate+ papaf.'!K42 -> 7363200
B20: 2 | C20: Ndrysh.gjend.lik. | E20: =E21-D21 -> -183915.67
B21: a | C21: Total gjendje lik. | D21: =D22+D23 -> 1468393.5 | E21: =E22+E23 -> 1284477.8
B22: b | C22: Gjendje lik.bankë | D22: =Analiza_KPA!O33 -> 268393.5 | E22: =[1]sp_NRP_Balance!$L$174 -> 84477.83
B23: c | C23: Gjendje lik.cash | D23: =Analiza_KPA!O34 -> 1200000 | E23: =D23 -> 1200000
B25: IV | C25: DETYRIME | D25: =SUM(D26:D28) -> 0 | E25: =SUM(E26:E28) -> 0
B26: 1 | C26: Detyrime ndaj shoq."KDK" ShPK | D26: - | E26: -
B27: 2 | C27: Detyrim ndaj A.Ramadani | D27: - | E27: -
B28: 3 | C28: Detyrim ndaj babait | D28: - | E28: -
B30: V | C30: PASURI NETO: V = III - IV | E30: =E18-E25 -> 7179284.3
B48: VI | C48: REZULTATI FIN. VI = I - II - V | E48: =E5-E9-E30 -> -6942947.8

Sheet KK
C3: 1993 | D3: 1994 | E3: 1995 | F3: 1996 | G3: 1997 | H3: 1998 | I3: 1999 | J3: 2000 | K3: 2001 | L3: 2002 | M3: 2003 | N3: 2004 | O3: 2005 | P3: 2006 | Q3: 2007 | R3: 2008 | S3: 2009 | T3: 2010 | U3: 2011 | V3: 2012 | W3: 2013 | X3: 2014 | Y3: 2015 | Z3: 2016 | AA3: 2017 | AB3: 2018 | AC3: 2019 | AJ3: Për reference më poshtë është paraqitur një tabelë përmbledhëse me shpenzimet vjetore sipas tre varianteve për një familje me 4 persona
B4: euro | J4: 132.57 | K4: 120.72 | L4: 140.18 | M4: 133.65 | N4: 126.74 | O4: 122.54 | P4: 123.703 | Q4: 120.91 | R4: 123.1825 | S4: 137.17 | T4: 138.81 | U4: 138.3 | V4: 139.72 | W4: 140.21 | X4: 140.11 | Y4: 137.65 | Z4: 135.27 | AA4: 132.95 | AB4: 123.42 | AC4: 121.77
B5: usd | C5: 102.06 | D5: 94.62 | E5: 92.79 | F5: 104.5 | G5: 148.93 | H5: 150.64 | I5: 137.69 | J5: 142.64 | K5: 136.55 | L5: 133.74 | M5: 108.69 | N5: 94.58 | O5: 103.33 | P5: 93.672 | Q5: 83.03 | R5: 90.96 | S5: 93.98 | T5: 104.95 | U5: 105.08 | V5: 106.57 | W5: 102.38 | X5: 113.64 | Y5: 126.64 | Z5: 128.29 | AA5: 111.1 | AB5: 107.82 | AC5: 108.64 | AJ5: VITET | AK5: 2003 | AL5: 2004 | AM5: 2005 | AN5: 2006 | AO5: 2007 | AP5: 2008 | AQ5: 2009 | AR5: 2010 | AS5: 2011 | AT5: 2012 | AU5: 2013 | AV5: 2014 | AW5: 2015 | AX5: 2016
B6: GBP | J6: 212.23 | K6: 197.86 | L6: 215.31 | M6: 189.92 | N6: 178.69 | O6: 178.65 | P6: 184.65 | Q6: 166.02 | R6: 127.66 | S6: 154.64 | T6: 161.46 | U6: 165.92 | V6: 171.18 | W6: 168.39 | X6: 179.48 | Y6: 186.59 | Z6: 157.56 | AA6: 149.95 | AB6: 137.42 | AC6: 143 | AJ6: INSTAT | AK6: 342252 | AL6: 342252 | AM6: 342252 | AN6: 342252 | AO6: 342252 | AP6: 385152 | AQ6: 385152 | AR6: 385152 | AS6: 385152 | AT6: 385152 | AU6: 385152 | AV6: 360060 | AW6: 400452 | AX6: 397224
AG7: ILDKPKI | AH7: 642857.14 | AI7: 642857.14 | AJ7: 642857.14 | AK7: 642857.14 | AL7: 642857.14 | AM7: 642857.14 | AN7: 642857.14 | AO7: 642857.14 | AP7: 642857.14 | AQ7: 642857.14 | AR7: 642857.14 | AS7: 642857.14 | AT7: 642857.14 | AU7: 642857.14
B9: Ref. ILDKPIK nr.804/1 prot.dt.29.01.2019
J10: 2000 | K10: 2001 | L10: 2002 | M10: 2003 | N10: 2004 | O10: 2005 | P10: 2006 | Q10: 2007 | R10: 2008 | S10: 2009 | T10: 2010 | U10: 2011 | V10: 2012 | W10: 2013 | X10: 2014 | Y10: 2015 | Z10: 2016 | AA10: 2017 | AB10: 2018
B11: per fryme | J11: 108000 | K11: 108000 | L11: 93894 | M11: 93964 | N11: 93964 | O11: 109557 | P11: 109557 | Q11: 136620 | R11: 136620 | S11: 136620 | T11: 136620 | U11: 136620 | V11: 139548 | W11: 141024 | X11: 219998 | Y11: 224276 | Z11: 235092 | AA11: 238054.05 | AB11: 246275.68
B12: 2 familjare | J12: 216000 | K12: 216000 | L12: 187788 | M12: 187928 | N12: 187928 | O12: 219114 | P12: 219114 | Q12: 273240 | R12: 273240 | S12: 273240 | T12: 273240 | U12: 273240 | V12: 279096 | W12: 282048 | X12: 439996 | Y12: 448552 | Z12: 470184 | AA12: 476108.11 | AB12: 492551.35
B13: 3 familjare | J13: 324000 | K13: 324000 | L13: 281682 | M13: 281892 | N13: 281892 | O13: 328671 | P13: 328671 | Q13: 409860 | R13: 409860 | S13: 409860 | T13: 409860 | U13: 409860 | V13: 418644 | W13: 423072 | X13: 659994 | Y13: 672828 | Z13: 705276 | AA13: 714162.16 | AB13: 738827.03
B14: 4 familjare | J14: 432000 | K14: 432000 | L14: 375576 | M14: 375856 | N14: 375856 | O14: 438228 | P14: 438228 | Q14: 546480 | R14: 546480 | S14: 546480 | T14: 546480 | U14: 546480 | V14: 558192 | W14: 564096 | X14: 879992 | Y14: 897104 | Z14: 940368 | AA14: 952216.22 | AB14: 985102.7
B15: 5 familjare | J15: 540000 | K15: 540000 | L15: 469470 | M15: 469820 | N15: 469820 | O15: 547785 | P15: 547785 | Q15: 683100 | R15: 683100 | S15: 683100 | T15: 683100 | U15: 683100 | V15: 697740 | W15: 705120 | X15: 1099990 | Y15: 1121380 | Z15: 1175460 | AA15: 1190270.3 | AB15: 1231378.4
B16: 6 familjare | J16: 648000 | K16: 648000 | L16: 563364 | M16: 563784 | N16: 563784 | O16: 657342 | P16: 657342 | Q16: 819720 | R16: 819720 | S16: 819720 | T16: 819720 | U16: 819720 | V16: 837288 | W16: 846144 | X16: 1319988 | Y16: 1345656 | Z16: 1410552 | AA16: 1428324.3 | AB16: 1477654.1
B17: 7 familjare | J17: 756000 | K17: 756000 | L17: 657258 | M17: 657748 | N17: 657748 | O17: 766899 | P17: 766899 | Q17: 956340 | R17: 956340 | S17: 956340 | T17: 956340 | U17: 956340 | V17: 976836 | W17: 987168 | X17: 1539986 | Y17: 1569932 | Z17: 1645644 | AA17: 1666378.4 | AB17: 1723929.7
B18: 8 familjare | J18: 864000 | K18: 864000 | L18: 751152 | M18: 751712 | N18: 751712 | O18: 876456 | P18: 876456 | Q18: 1092960 | R18: 1092960 | S18: 1092960 | T18: 1092960 | U18: 1092960 | V18: 1116384 | W18: 1128192 | X18: 1759984 | Y18: 1794208 | Z18: 1880736 | AA18: 1904432.4 | AB18: 1970205.4
A20: Shenim | B20: Sipas Shkreses se sipercituar te ILDKPIK shpenzimet per fryme te vitin 2007 jane 235,968 Leke, vlere e cila eshte 2-fish ne krahasim me Vitet 2006 dhe 2008.
B21: Në praktiken tonë Vlera e shpenzimeve per fryme merret e barabartë me Vitin 2008.
B22: Kjo rritje dhe pastaj ulje nuk bazohet ne shifrat e Inflacionit Zyrtar i cili ne V.2006 eshte 2,5%, V.2007-3% dhe V.2008-2%.
B23: http://open.data.al/sq/lajme/lajm/lang/sq/id/71/Historik-i-Inflacionit-ne-Shqiperi
J28: 2000 | K28: 2001 | L28: 2002 | M28: 2003 | N28: 2004 | O28: 2005 | P28: 2006 | Q28: 2007 | R28: 2008 | S28: 2009 | T28: 2010 | U28: 2011 | V28: 2012 | W28: 2013 | X28: 2014 | Y28: 2015 | Z28: 2016 | AA28: 2017 | AB28: 2018
B29: 2 familjare | J29: 216000 | K29: 216000 | L29: 187788 | M29: 187928 | N29: 187928 | O29: 219114 | P29: 219114 | Q29: 273240 | R29: 273240 | S29: 273240 | T29: 273240 | U29: 273240 | V29: 279096 | W29: 282048 | X29: 439996 | Y29: 448552 | Z29: 470184 | AA29: 476108.11 | AB29: 492551.35
X32: =2900 -> 2900
X33: =X32*X4 -> 406319

Sheet ID
C2: Emer | D2: Atesi | E2: Mbiemer | F2: Datelindje
B3: S.R. | C3: Arben | D3: Sinan | E3: Sharra | F3: 29.03.1973
B4: B/Sh | C4: Flutura | D4: Halit | E4: Sharra | F4: 09.05.1974
B5: I biri | C5: Enea | D5: Arben | E5: Sharra | F5: 02.09.1997
B6: E bija | C6: Ersa | D6: Arben | E6: Sharra | F6: 22.01.2002

Sheet Analiza 
L2: Ne detyre ne date 16.07.2004
C3: 1996 | D3: 1997 | E3: 1998 | F3: 1999 | G3: 2000 | H3: 2001 | I3: 2002 | J3: 2003 | K3: 1996-2003 | L3: 2004 | M3: 2005 | N3: 2006 | O3: 2007 | P3: 2008 | Q3: 2009 | R3: 2010 | S3: 2011 | T3: 2012 | U3: 2013 | V3: 2014 | W3: 2015 | X3: 2016 | Y3: Totali | Z3: Deklarata Vetting
B4: Pasuria | D4: =SUM(D5:D11) -> 0 | E4: =SUM(E5:E11) -> 0 | F4: =SUM(F5:F11) -> 0 | G4: =SUM(G5:G11) -> 0 | H4: =SUM(H5:H11) -> 0 | I4: =SUM(I5:I11) -> 0 | J4: =SUM(J5:J11) -> 267300 | K4: 267300 | L4: =SUM(L5:L11) -> 0 | M4: =SUM(M5:M11) -> 604815.44 | N4: =SUM(N5:N11) -> 863578.06 | O4: =SUM(O5:O11) -> 339106.54 | P4: =SUM(P5:P11) -> 12754398 | Q4: =SUM(Q5:Q11) -> -1543902.5 | R4: =SUM(R5:R11) -> 1270.44 | S4: =SUM(S5:S11) -> 413557.02 | ... Z4: =SUM(Z5:Z11) -> 9673
B5: Shtepi Banimi sip 134.5 M2 | K5: 0 | L5: 0 | M5: 0 | N5: 0 | O5: 0 | P5: 0 | Y5: =SUM(K5:X5) -> 0
B6: Mercedes Benz 2003 | J6: =2000*KK!M4 -> 267300 | K6: 267300 | L6: 0 | M6: 0 | N6: 0 | O6: 0 | P6: 0 | Y6: =SUM(K6:X6) -> 267300
B7: Apartament banimi me sip 128.1 m2 | K7: 0 | L7: 0 | M7: 0 | N7: 0 | O7: 0 | P7: =94830*KK!R4 -> 11681396 | Y7: =SUM(K7:X7) -> 11681396
B8: Automjet Daimler Chrysler | K8: 0 | L8: 0 | M8: 0 | N8: 0 | O8: 0 | P8: =5500*KK!R4 -> 677503.75 | Y8: =SUM(K8:X8) -> 677503.75
B9: Garazhd me sip 45 m2 | K9: 0 | L9: 0 | M9: 0 | N9: 0 | O9: 0 | P9: 0 | U9: =11000*KK!W4 -> 1542310 | Y9: =SUM(K9:X9) -> 1542310
B10: Automjet Mercedes Benz 02.03.2017 | K10: 0 | L10: 0 | M10: 0 | N10: 0 | O10: 0 | P10: 0 | Y10: =SUM(K10:X10) -> 0
B11: Ndryshim likujditeti | J11: =+' Likujditete'!O58 -> 0 | K11: 0 | L11: =+' Likujditete'!P58 -> 0 | M11: =+' Likujditete'!Q58 -> 604815.44 | N11: =+' Likujditete'!R58 -> 863578.06 | O11: =+' Likujditete'!S58 -> 339106.54 | P11: =+' Likujditete'!T58 -> 395498.02 | Q11: =+' Likujditete'!U58 -> -1543902.5 | R11: =+' Likujditete'!V58 -> 1270.44 | S11: =+' Likujditete'!W58 -> 413557.02 | ... X11: =+' Likujditete'!AB58 -> 666773.15 | Y11: =SUM(K11:X11) -> 2084250.9 | Z11: =+' Likujditete'!AD58 -> 9673
B12: Total Likujditeti | J12: =+' Likujditete'!O57 -> 0 | K12: 0 | L12: =+' Likujditete'!P57 -> 0 | M12: =+' Likujditete'!Q57 -> 604815.44 | N12: =+' Likujditete'!R57 -> 1468393.5 | O12: =+' Likujditete'!S57 -> 1807500 | P12: =+' Likujditete'!T57 -> 2202998.1 | Q12: =+' Likujditete'!U57 -> 659095.6 | R12: =+' Likujditete'!V57 -> 660366.04 | S12: =+' Likujditete'!W57 -> 1073923.1 | ... X12: =+' Likujditete'!AB57 -> 2084250.9 | Y12: =SUM(K12:X12) -> 15699313 | Z12: =+' Likujditete'!AD57 -> 1287604.9
B13: cash | D13: 0 | E13: 0 | F13: 0 | G13: 0 | H13: 0 | I13: 0 | J13: =+' Likujditete'!O54 -> 0 | K13: 0 | L13: =+' Likujditete'!P54 -> 0 | M13: =+' Likujditete'!Q56 -> 600000 | N13: =+' Likujditete'!R56 -> 1200000 | O13: =+' Likujditete'!S56 -> 1750000 | P13: =+' Likujditete'!T56 -> 2150000 | Q13: =+' Likujditete'!U56 -> 650000 | R13: =+' Likujditete'!V56 -> 611696 | S13: =+' Likujditete'!W56 -> 1011696 | T13: =+' Likujditete'!X56 -> 1151696 | ... X13: =+' Likujditete'!AB56 -> 862319 | Y13: =SUM(K13:X13) -> 12751741 | Z13: =+' Likujditete'!AD54 -> 0
B14: Detyrime | C14: =SUM(C15:C23) -> 0 | D14: =SUM(D15:D23) -> 0 | E14: =SUM(E15:E23) -> 0 | F14: =SUM(F15:F23) -> 0 | G14: =SUM(G15:G23) -> 0 | H14: =SUM(H15:H23) -> 0 | I14: =SUM(I15:I23) -> 0 | J14: =SUM(J15:J23) -> 0 | K14: 0 | L14: =SUM(L15:L23) -> 0 | M14: =SUM(M15:M23) -> 0 | N14: =SUM(N15:N23) -> 0 | O14: =SUM(O15:O23) -> 0 | P14: =SUM(P15:P23) -> 11430104 | Q14: =SUM(Q15:Q23) -> -2532838.6 | R14: =SUM(R15:R23) -> -855658.15 | S14: =SUM(S15:S23) -> -1037710.5 | ... X14: =SUM(X15:X23) -> 0 | Y14: =SUM(K14:X14) -> -1013066.1 | Z14: =SUM(Z15:Z23) -> 0
B15: Kredi ne NBG 46,000 Euro | K15: 0 | L15: 0 | M15: 0 | N15: 0 | O15: 0 | P15: =46000*KK!R4 -> 5666395 | Y15: =SUM(K15:X15) -> 5666395
B16: Shlyerje e kredise ne NBG 46,000 Euro | K16: 0 | L16: 0 | M16: 0 | N16: 0 | O16: 0 | P16: =-'Kredi ne NBG '!D6 -> -255234.14 | Q16: =-'Kredi ne NBG '!E6 -> -2532838.6 | R16: =-'Kredi ne NBG '!F6 -> -855658.15 | S16: =-'Kredi ne NBG '!G6 -> -1037710.5 | T16: =-'Kredi ne NBG '!H6 -> -684628 | U16: =-'Kredi ne NBG '!I6 -> -267941.31 | V16: =-'Kredi ne NBG '!J6 -> -2387474.4 | Y16: =SUM(K16:X16) -> -8021485.1
B17: Detyrim ndaj KDK | K17: 0 | L17: 0 | M17: 0 | N17: 0 | O17: 0 | P17: =+P7 -> 11681396 | Y17: =SUM(K17:X17) -> 11681396
B18: Shlyerje detyrim ndaj KDK | K18: 0 | L18: 0 | M18: 0 | N18: 0 | O18: 0 | P18: =-(45968*KK!R4) -> -5662453.2 | Q18: 0 | R18: 0 | S18: 0 | T18: =-5000*KK!V4 -> -698600 | U18: =-(285)*KK!W4 -> -39959.85 | W18: =-(230+24400+5000)*KK!Y4 -> -4078569.5 | Y18: =SUM(K18:X18) -> -10479583 | Z18: 0
B19: Hua nga babai 4000 Euro 2013 | K19: 0 | L19: 0 | M19: 0 | N19: 0 | O19: 0 | P19: 0 | Y19: =SUM(K19:X19) -> 0
B20: Hua nga nena 2000 Euro 2017 | K20: 0 | L20: 0 | M20: 0 | N20: 0 | O20: 0 | P20: 0 | Y20: =SUM(K20:X20) -> 0
B21: Shlyerje Hua ndaj nenes | K21: 0 | L21: 0 | M21: 0 | N21: 0 | O21: 0 | P21: 0 | U21: 0 | Y21: =SUM(K21:X21) -> 0
B22: Detyrim per garazhdin | K22: 0 | L22: 0 | M22: 0 | N22: 0 | O22: 0 | P22: 0 | U22: =+U9 -> 1542310 | Y22: =SUM(K22:X22) -> 1542310
B23: Shlyerje detyrim per garazhdin | K23: 0 | L23: 0 | M23: 0 | N23: 0 | O23: 0 | P23: 0 | U23: =-10000*KK!W4 -> -1402100 | Y23: =SUM(K23:X23) -> -1402100
B24: Pasuria Neto | C24: =+C4-C14 -> 0 | D24: =+D4-D14 -> 0 | E24: =+E4-E14 -> 0 | F24: =+F4-F14 -> 0 | G24: =+G4-G14 -> 0 | H24: =+H4-H14 -> 0 | I24: =+I4-I14 -> 0 | J24: =+J4-J14 -> 267300 | K24: 267300 | L24: =+L4-L14 -> 0 | M24: =+M4-M14 -> 604815.44 | N24: =+N4-N14 -> 863578.06 | O24: =+O4-O14 -> 339106.54 | P24: =+P4-P14 -> 1324294.1 | Q24: =+Q4-Q14 -> 988936.1 | R24: =+R4-R14 -> 856928.59 | S24: =+S4-S14 -> 1451267.6 | ... X24: =+X4-X14 -> 666773.15 | Y24: =SUM(K24:X24) -> 17265827 | Z24: =+Z4-Z14 -> 9673
K25: 0 | Y25: =SUM(K25:X25) -> 0
B26: Te ardhura | C26: =SUM(C27:C32) -> 60154 | D26: =SUM(D27:D32) -> 231024 | E26: =SUM(E27:E32) -> 360525 | F26: =SUM(F27:F32) -> 461249 | G26: =SUM(G27:G32) -> 603437 | H26: =SUM(H27:H32) -> 636075.5 | I26: =SUM(I27:I32) -> 608853.5 | J26: =SUM(J27:J32) -> 765140 | K26: 3726458 | L26: =SUM(L27:L32) -> 933625 | M26: =SUM(M27:M32) -> 1145795 | N26: =SUM(N27:N32) -> 1093156 | O26: =SUM(O27:O32) -> 1029704 | P26: =SUM(P27:P32) -> 1623856 | Q26: =SUM(Q27:Q32) -> 1349735 | R26: =SUM(R27:R32) -> 1389475 | S26: =SUM(S27:S32) -> 1519983 | ... X26: =SUM(X27:X32) -> 2607678 | Y26: =SUM(K26:X26) -> 30215825 | Z26: =SUM(Z27:Z32) -> 175673
B27: Te ardhurat e subjektit | C27: =+'Te Ardhurat '!D9 -> 60154 | D27: =+'Te Ardhurat '!E9 -> 231024 | E27: =+'Te Ardhurat '!F9 -> 360525 | F27: =+'Te Ardhurat '!G9 -> 390615 | G27: =+'Te Ardhurat '!H9 -> 442564 | H27: =+'Te Ardhurat '!I9 -> 446705 | I27: =+'Te Ardhurat '!J9 -> 414633 | J27: =+'Te Ardhurat '!K9 -> 473716 | K27: 2819936 | L27: =+'Te Ardhurat '!L9 -> 606194 | M27: =+'Te Ardhurat '!M9 -> 818245 | N27: =+'Te Ardhurat '!N9 -> 815652 | O27: =+'Te Ardhurat '!O9 -> 841418 | P27: =+'Te Ardhurat '!P9 -> 905278 | Q27: =+'Te Ardhurat '!Q9 -> 851469 | R27: =+'Te Ardhurat '!R9 -> 814286 | S27: =+'Te Ardhurat '!S9 -> 942368 | ... X27: =+'Te Ardhurat '!X9 -> 1170841 | Y27: =SUM(K27:X27) -> 14702262 | Z27: =+'Te Ardhurat '!Z9 -> 99845
B28: Te ardhurat e Bshortes se Subjektit | C28: =+'Te Ardhurat '!D25 -> 0 | D28: =+'Te Ardhurat '!E25 -> 0 | E28: =+'Te Ardhurat '!F25 -> 0 | F28: =+'Te Ardhurat '!G25 -> 70634 | G28: =+'Te Ardhurat '!H25 -> 160873 | H28: =+'Te Ardhurat '!I25 -> 189370.5 | I28: =+'Te Ardhurat '!J25 -> 194220.5 | J28: =+'Te Ardhurat '!K25 -> 291424 | K28: 906522 | L28: =+'Te Ardhurat '!L25 -> 327431 | M28: =+'Te Ardhurat '!M25 -> 327550 | N28: =+'Te Ardhurat '!N25 -> 277504 | O28: =+'Te Ardhurat '!O25 -> 188286 | P28: =+'Te Ardhurat '!P25 -> 318578 | Q28: =+'Te Ardhurat '!Q25 -> 498266 | R28: =+'Te Ardhurat '!R25 -> 575189 | S28: =+'Te Ardhurat '!S25 -> 577615 | ... X28: =+'Te Ardhurat '!X25 -> 904419 | Y28: =SUM(K28:X28) -> 7649445 | Z28: =+'Te Ardhurat '!Z25 -> 75828
B29: Te ardhura nga shitja e automjetit Mercedes Benz dt 09.09.2008 shuma 400,000 leke | C29: =+'Te Ardhurat '!D33 -> 0 | D29: =+'Te Ardhurat '!E33 -> 0 | E29: =+'Te Ardhurat '!F33 -> 0 | F29: =+'Te Ardhurat '!G33 -> 0 | G29: =+'Te Ardhurat '!H33 -> 0 | H29: =+'Te Ardhurat '!I33 -> 0 | I29: =+'Te Ardhurat '!J33 -> 0 | J29: =+'Te Ardhurat '!K33 -> 0 | K29: 0 | L29: =+'Te Ardhurat '!L33 -> 0 | M29: =+'Te Ardhurat '!M33 -> 0 | N29: =+'Te Ardhurat '!N33 -> 0 | O29: =+'Te Ardhurat '!O33 -> 0 | P29: =+'Te Ardhurat '!P33 -> 400000 | Q29: =+'Te Ardhurat '!Q33 -> 0 | R29: =+'Te Ardhurat '!R33 -> 0 | S29: =+'Te Ardhurat '!S33 -> 0 | ... X29: =+'Te Ardhurat '!X33 -> 0 | Y29: =SUM(K29:X29) -> 400000 | Z29: =+'Te Ardhurat '!Z33 -> 0
B30: PARADHENIE per shitjen e baneses ne K.Kamez | K30: 0 | L30: =+'Te Ardhurat '!L34 -> 0 | M30: =+'Te Ardhurat '!M34 -> 0 | N30: =+'Te Ardhurat '!N34 -> 0 | O30: =+'Te Ardhurat '!O34 -> 0 | P30: =+'Te Ardhurat '!P34 -> 0 | V30: =20000*KK!X4 -> 2802200 | W30: =30000*KK!Y4 -> 4129500 | Y30: =SUM(K30:X30) -> 6931700
B31: Te ardhura nga shitja e automjetit Mercedes Benz dt 15.03.2016 shuma 3,800 Euro | C31: =+'Te Ardhurat '!D34 -> 0 | D31: =+'Te Ardhurat '!E34 -> 0 | E31: =+'Te Ardhurat '!F34 -> 0 | F31: =+'Te Ardhurat '!G34 -> 0 | G31: =+'Te Ardhurat '!H34 -> 0 | H31: =+'Te Ardhurat '!I34 -> 0 | I31: =+'Te Ardhurat '!J34 -> 0 | J31: =+'Te Ardhurat '!K34 -> 0 | K31: 0 | L31: =+'Te Ardhurat '!L35 -> 0 | M31: =+'Te Ardhurat '!M35 -> 0 | N31: =+'Te Ardhurat '!N35 -> 0 | O31: =+'Te Ardhurat '!O35 -> 0 | P31: =+'Te Ardhurat '!P35 -> 0 | Q31: =+'Te Ardhurat '!Q34 -> 0 | R31: =+'Te Ardhurat '!R34 -> 0 | S31: =+'Te Ardhurat '!S34 -> 0 | T31: =+'Te Ardhurat '!T34 -> 0 | U31: =+'Te Ardhurat '!U34 -> 0 | V31: =+'Te Ardhurat '!V34 -> 0 | W31: =+'Te Ardhurat '!W34 -> 0 | X31: =3800*KK!X4 -> 532418 | Y31: =SUM(K31:X31) -> 532418 | Z31: =+'Te Ardhurat '!Z34 -> 0
B32: Te ardhura nga shitja e baneses ne K.Kamez kontrete shitje dt 16.06.2017 | K32: 0 | L32: =+'Te Ardhurat '!L36 -> 0 | M32: =+'Te Ardhurat '!M36 -> 0 | N32: =+'Te Ardhurat '!N36 -> 0 | O32: =+'Te Ardhurat '!O36 -> 0 | P32: 0 | Y32: =SUM(K32:X32) -> 0
B33: Shpenzime | C33: =SUM(C34:C41) -> 19850.82 | D33: =SUM(D34:D41) -> 76237.92 | E33: =SUM(E34:E41) -> 118973.25 | F33: =SUM(F34:F41) -> 152212.17 | G33: =SUM(G34:G41) -> 324000 | H33: =SUM(H34:H41) -> 324000 | I33: =SUM(I34:I41) -> 367751.5 | J33: =SUM(J34:J41) -> 375856 | K33: 1758881.7 | L33: =SUM(L34:L41) -> 375856 | M33: =SUM(M34:M41) -> 438228 | N33: =SUM(N34:N41) -> 438228 | O33: =SUM(O34:O41) -> 547212 | P33: =SUM(P34:P41) -> 550907.47 | Q33: =SUM(Q34:Q41) -> 547212 | R33: =SUM(R34:R41) -> 547830 | S33: =SUM(S34:S41) -> 886665 | ... X33: =SUM(X34:X41) -> 1454194.2 | Y33: =SUM(K33:X33) -> 12407891 | Z33: =SUM(Z34:Z41) -> 113918.35
B34: Shpenzime Jetike | C34: =+(C27+C28)*0.33 -> 19850.82 | D34: =+(D27+D28)*0.33 -> 76237.92 | E34: =+(E27+E28)*0.33 -> 118973.25 | F34: =+(F27+F28)*0.33 -> 152212.17 | G34: =+KK!J13 -> 324000 | H34: =+KK!K13 -> 324000 | I34: =+KK!L13/12*1+KK!L14/12*11 -> 367751.5 | J34: =+KK!M14 -> 375856 | K34: 1758881.7 | L34: =+KK!N14 -> 375856 | M34: =+KK!O14 -> 438228 | N34: =+KK!P14 -> 438228 | O34: =+KK!Q14 -> 546480 | P34: =+KK!R14 -> 546480 | Q34: =+KK!S14 -> 546480 | R34: =+KK!T14 -> 546480 | S34: =+KK!U14 -> 546480 | ... X34: =+KK!Z14 -> 940368 | Y34: =SUM(K34:X34) -> 9583345.7 | Z34: =+KK!AA14/12 -> 79351.351
B35: TIMS | K35: 0 | L35: 0 | M35: 0 | N35: 0 | O35: 0 | P35: =+TIMS!C6 -> 3695.475 | Q35: =+TIMS!D6 -> 0 | R35: =+TIMS!E6 -> 0 | S35: =+TIMS!F6 -> 338835 | T35: =+TIMS!G6 -> 0 | U35: =+TIMS!H6 -> 392588 | V35: =+TIMS!I6 -> 140110 | W35: =+TIMS!J6 -> 37165.5 | X35: =+TIMS!K6 -> 31054 | Y35: =SUM(K35:X35) -> 943447.97 | Z35: =+TIMS!M6 -> 7977 | AB35: 2196
B36: Shpenzime per legalizimin e Godine banimi 3 kateshe 01.07.2015 | K36: 0 | L36: 0 | M36: 0 | N36: 0 | O36: 0 | P36: 0 | W36: =(500000*0.1)+360000 -> 410000 | Y36: =SUM(K36:X36) -> 410000
B37: Shpenzime per Taksat vendore te tokes bujqesore | K37: 0 | L37: 0 | M37: 0 | N37: 0 | O37: 732 | P37: 732 | Q37: 732 | R37: 1350 | S37: 1350 | T37: 1227 | U37: 1520.5 | V37: 1520.5 | W37: 1229 | X37: 1651.24 | Y37: =SUM(K37:X37) -> 12044.24
B38: Shpenzime per shkollimin e Enea Sharra | K38: 0 | L38: 0 | M38: 0 | N38: 0 | O38: 0 | P38: 0 | W38: =40000/10*4 -> 16000 | X38: 40000 | Y38: =SUM(K38:X38) -> 56000
B39: Shpenzime per shkollimin e Ersa Sharra Shkolla Faik Konica | K39: 0 | L39: 0 | M39: 0 | N39: 0 | O39: 0 | P39: 0 | U39: =1710/10*4*KK!W4 -> 95903.64 | V39: =+(1710/10*6+1800/10*4)*KK!X4 -> 244632.06 | W39: =+(1800/10*4+1800/10*6)*KK!Y4 -> 247770 | X39: =+(1800/10*6+2000/10*4)*KK!Z4 -> 254307.6 | Y39: =SUM(K39:X39) -> 842613.3 | Z39: =+(200)*KK!AA4 -> 26590
B40: Shpenzime per shkollimin e Ersa Sharra Shkolla Elite | K40: 0 | L40: 0 | M40: 0 | N40: 0 | O40: 0 | P40: 0 | Y40: =SUM(K40:X40) -> 0
B41: Shpenzime Mobilimi | K41: 0 | L41: 0 | M41: 0 | N41: 0 | O41: 0 | P41: 0 | V41: =4000*KK!X4/3 -> 186813.33 | W41: 186813.33 | X41: 186813.33 | Y41: =SUM(K41:X41) -> 560440
...

Sheet  Likujditete
B3: Subjekti Arben Sharra | C3: BANKA | D3: Nr Llogarise | E3: monedha | H3: 1996 | I3: 1997 | J3: 1998 | K3: 1999 | L3: 2000 | M3: 2001 | N3: 2002 | O3: 2003 | P3: 2004 | Q3: 2005 | R3: 2006 | S3: 2007 | T3: 2008 | U3: 2009 | V3: 2010 | W3: 2011 | X3: 2012 | Y3: 2013 | Z3: 2014 | AA3: 2015 | AB3: 2016 | AC3: TOTAL | AD3: DVETTING
B5: Llogari kredie | C5: NBG | D5: 18791341016015 | E5: Euro | T5: =0.41*KK!R4 -> 50.504825 | U5: =0.62*KK!S4 -> 85.0454 | V5: =4.65*KK!T4 -> 645.4665 | W5: =0.37*KK!U4 -> 51.171 | X5: 0 | Y5: =2.82*KK!W4 -> 395.3922 | Z5: =24.85*KK!X4 -> 3481.7335
B6: kestet e paguara | E6: Euro | T6: =346+345+345+346+345+345 -> 2072 | U6: =345+346+345.24+345+345.24+15000+230.24+356.24+231+230+230+231+230 -> 18464.96 | V6: =230*7+231+230.24+231+126+231+3405+100 -> 6164.24 | W6: =201+204+205+205+205+205+205+3290+180.86+180.86+180.86+180.75+2060 -> 7503.33 | X6: =165+165+165+165+162+165+165+3090+198+180+150+130 -> 4900 | Y6: =140+138+138+140+140+140+137+140+138+140+100+150+130+140 -> 1911 | Z6: =140*8+100+135+135+15550 -> 17040
U7: 15000 eruo cash dep dt 28 maj 2009 | V7: 3405 euro cash dep dt 25.11.2010 | W7: 3290 euro cash dep dt 01 gusht 2011 | X7: 3090 euro Cash depozite dt 13 gusht 2012 | Z7: 15550 euro cash depozit dt 07 nentor 2014
W8: 2060 Euro cash dep dt 30 dhjetor 2011
B10: Gjendja 31.12….. | C10: RZB | D10: 525206 | E10: lek | Q10: 4568.44 | R10: 268021.29 | S10: 57127.83 | T10: 52625.52 | U10: 11.43 | V10: 233.04 | W10: 308.06 | X10: -60.17 | Y10: 598.48 | Z10: 83216.14 | AA10: 6144.87 | AB10: 411888.02 | AD10: 451733.02
B11: llogari page | Q11: =27726+65858+69069+65221+83364+63936+65221+68432+10000+67305+62123 -> 648255 | R11: =23495+68432+65081+65081+68292+68292+68292+64088+62445+74824+71362+79158+15000+42095 -> 835937 | S11: =24027+71195+69348+75976+72976+72703+40605+36021+66228+76627+79229+65136+68450+14507+49943+30000 -> 912971 | T11: =64450+85761+76775+76438+74579+74326+6449+93825+68121+74716+70320+70320+52500 -> 888580 | U11: =26820+70320+66495+66495+91257+66495+77050+66495+66495+66495+66495+77772 -> 808684 | V11: =31772+49833+65772+65773+65772+65772+65772+65772+65380+68872+66876+49537+12564+75877+9000+5381 -> 829725 | W11: =67774+72258+77639+72258+88401+72258+66877+83020+76833+85400+69526+87247+9000 -> 928491 | X11: =81650+69526+80718+80718+86314+69526+69526+81151+74699+69249+73809+71264+77012+9000 -> 994162 | Y11: =71264+77012+82760+71264+71264+73180+71264+72801+72477+72477+85081+78249+11714 -> 910807 | Z11: =78249+89195+120275+89195+95857+95857+95857+108513+89014+105426+60648+51843+978 -> 1080907 | AA11: =90762+86345+95055+91791+96155+89608+102577+89608+99519+91334+91334+96334 -> 1120422 | AB11: =93834+97167+91334+96333+91334+86941+91334+93060+93060+114222+104537+111673 -> 1164829 | AD11: 99845
B15: Gjendja 31.12….. | C15: RZB | D15: 525206 | E15: Euro
B17: TOTALI | I17: =SUM(I4:I16) -> 0 | J17: =SUM(J4:J16) -> 0 | K17: =SUM(K4:K16) -> 0 | L17: =SUM(L4:L16) -> 0 | M17: =SUM(M4:M16) -> 0 | N17: =SUM(N4:N16) -> 0 | O17: =+O10+O15 -> 0 | P17: =+P10+P15 -> 0 | Q17: =+Q10+Q15 -> 4568.44 | R17: =+R10+R15 -> 268021.29 | S17: =+S10+S15 -> 57127.83 | T17: =+T10+T15 -> 52625.52 | U17: =+U10+U15 -> 11.43 | V17: =+V10+V15 -> 233.04 | ... AD17: =+AD10+AD15 -> 451733.02
B19: B/Shhorti I subjektit | C19: BANKA | D19: Nr Llogarise | E19: monedha | H19: 1996 | I19: 1997 | J19: 1998 | K19: 1999 | L19: 2000 | M19: 2001 | N19: 2002 | O19: 2003 | P19: 2004 | Q19: 2005 | R19: 2006 | S19: 2007 | T19: 2008 | U19: 2009 | V19: 2010 | W19: 2011 | X19: 2012 | Y19: 2013 | Z19: 2014 | AA19: 2015 | AB19: 2016 | AC19: TOTAL | AD19: DVETTING
B21: Gjendja 31.12….. | C21: Tirana Bank | D21: 267207 | E21: lek | U21: 9084 | V21: 48437 | W21: 61919 | X21: 61214.23 | Y21: 2419.35 | Z21: 0
B22: llogari page pagat nga 27 shkurt 2009-31 dhjetor 2013 | U22: =33225+45567*9+53756+9000 -> 506084 | V22: =45591*9+50664+49750+9000+47620 -> 567353 | W22: =47620*9+49785+38549+9000+52865 -> 578779 | X22: =48574*5+50807+37408+49133+49733+49058*3+9000 -> 586125 | Y22: =49058*3+37781+50750+50733*3+51790+51281*2+4490+46566 -> 593312
B24: Gjendja 31.12….. | C24: BKT | D24: 507253775 | E24: lek | Q24: 247 | R24: 372.21 | S24: =R24 -> 372.21 | T24: 372.54 | U24: 0.17 | V24: 0 | W24: 0 | X24: 0 | Y24: 0 | Z24: 463393.52 | AA24: 605013.92 | AB24: 810043.92 | AD24: 835871.92
B25: llogari page paga kaluar Prill 2005-tetor 2006 llogari page janar 2009 llogari page janar 2014- 2020 | Q25: =27624*9+28379 -> 276995 | R25: =28379*8+40593 -> 267625 | U25: 26571 | Z25: =53229*3+55728*5+60228+62657+60228+60228 -> 681668 | AA25: =15660+60228+57256+58742+60625+54289+74890+68472+74890+74716+74890+74890+74890 -> 824438 | AB25: =73418+71313+74890+75140+75142*7+75828 -> 896583 | AD25: 75828
B33: TOTALI | I33: =SUM(I20:I32) -> 0 | J33: =SUM(J20:J32) -> 0 | K33: =SUM(K20:K32) -> 0 | L33: =SUM(L20:L32) -> 0 | M33: =SUM(M20:M32) -> 0 | N33: =SUM(N20:N32) -> 0 | O33: =+O21+O24 -> 0 | P33: =+P21+P24 -> 0 | Q33: =+Q21+Q24 -> 247 | R33: =+R21+R24 -> 372.21 | S33: =+S21+S24 -> 372.21 | T33: =+T21+T24 -> 372.54 | U33: =+U21+U24 -> 9084.17 | V33: =+V21+V24 -> 48437 | ... AD33: =+AD21+AD24 -> 835871.92
B36: Prinderit Hamide dhe Sinan Sharra | C36: BANKA | D36: Nr Llogarise | E36: monedha | H36: 1996 | I36: 1997 | J36: 1998 | K36: 1999 | L36: 2000 | M36: 2001 | N36: 2002 | O36: 2003 | P36: 2004 | Q36: 2005 | R36: 2006 | S36: 2007 | T36: 2008 | U36: 2009 | V36: 2010 | W36: 2011 | X36: 2012 | Y36: 2013 | Z36: 2014 | AA36: 2015 | AB36: 2016 | AC36: TOTAL | AD36: DVETTING
B37: Hamide Sharra 31.12…… | C37: Intesa san paolo | D37: 847639 | E37: lek | X37: 13525 | Y37: 22222.54 | Z37: 112722.54 | AA37: 442.54
B38: kjo llogari eshte perdorur per kalimin e ndihmes ekonomike paaftesi Sinan Sharr | X38: =10600*10+43200+43200+28800 -> 221200 | Y38: =10800*15+11100*4+22200 -> 228600 | Z38: =11100*20+22200*2+13500+13500+3000 -> 296400 | AA38: =11250*18+11530*2+22780*2+2000 -> 273120
B40: Hamide Sharra 31.12…… | C40: RZB | D40: 185095 | E40: Euro
B43: Sinan Sharra 31.12…… | C43: RZB | D43: 185095 | E43: USD | S43: 0 | T43: =5042*KK!R5 -> 458620.32 | U43: =5084.09*KK!S5 -> 477802.78 | V43: 0
B44: Depozite krijuar ne 22.08.2007 ne 100,000 USD | C44: Int. perf. nga depoz. | S44: =(104483.5-100000)*KK!Q5 -> 372265.01
B46: Hamide & Sinan Sharra | C46: Procredit | D46: 170205510001 | E46: Lek | V46: 0
B49: TOTALI | P49: =+P45 -> 0 | Q49: =+Q45 -> 0 | R49: =+R45 -> 0 | S49: =+S45 -> 0 | T49: =+T45 -> 0 | U49: =+U45 -> 0 | V49: =+V45 -> 0 | W49: =+W45 -> 0 | ... AB49: =+AB45 -> 0
H51: 1996 | I51: 1997 | J51: 1998 | K51: 1999 | L51: 2000 | M51: 2001 | N51: 2002 | O51: 2003 | P51: 2004 | Q51: 2005 | R51: 2006 | S51: 2007 | T51: 2008 | U51: 2009 | V51: 2010 | W51: 2011 | X51: 2012 | Y51: 2013 | Z51: 2014 | AA51: 2015 | AB51: 2016 | AC51: TOTAL | AD51: DVETTING
B52: NE DVP | O52: Deklarata para detyres nuk ka deklaruar gjendje cash | P52: nuk deklaron gjendje cash | Q52: Ne rubriken shtesa / pakesime deklaron 1. Likujditet I krijuar ne vitin 2005 shuma 600,000 leke 2. Likujditet nga shfrytezimi I tokes bujqesore 300,000 leke | R52: Ne rubriken shtesa / pakesime deklaron Likujditet I krijuar ne vitin 2006 shumen 600,000 leke dhe Likujditet nga shfrytezimi I tokes bujqesore 100,000 leke | S52: Ne rubriken shtesa / pakesime deklaron Likujditet I krijuar ne vitin 2007 shumen 550,000 leke dhe Likujditet nga shfrytezimi I tokes bujqesore 200,000 leke | T52: Ne rubriken shtesa / pakesime deklaron gjendje CASH krijuar pet vitin 2008 shumen 400,000 leke | U52: pakesime ne vleren 2,000,000 leke nga kursmiet e bera deri ne 31.12.2008 deklaron gjendje CASH 500,000 leke krijuar per vitin 2009 | V52: Deklaron pakesime likujditete ne vleren 838,304 leke deklaron gjendje CASH per vitin 2010 shumen 800,000 leke | W52: deklaron gejndje CASH shume 400,000,leke nga kursimet e te ardhurat e vitit 2011 | X52: Deklaron gjendje CASH shumen 140,000 leke (kursime te vitit 2012 | Y52: Nuk deklaron gjendje cash | Z52: deklaron te ardhura te kursyera nga paga RZBderi ne 31.12.2014 shuma 83216.14leke te ardhura te kursyera nga paga deri ne 31.12.2014 BKT shuma 463,393.52 leke Deklaron gjendje CASH krijuar per vitin 2014 shuma 400,000 leke dhe nga kursimet e te ardhurave shumwn 2,900 Euro | AA52: nuk deklaron cash | AB52: deklaron gjendje CASH 58,000 leke krijuar per 2016 | AD52: Nuk deklaron gjendje CASH
B53: TOTAL BANKA | I53: =+I49+I33+I17 -> 0 | J53: =+J49+J33+J17 -> 0 | K53: =+K49+K33+K17 -> 0 | L53: =+L33+L17 -> 0 | M53: =+M33+M17 -> 0 | N53: =+N33+N17 -> 0 | O53: =+O33+O17 -> 0 | P53: =+P33+P17 -> 0 | Q53: =+Q33+Q17 -> 4815.44 | R53: =+R33+R17 -> 268393.5 | S53: =+S33+S17 -> 57500.04 | ... AD53: =+AD33+AD17 -> 1287604.9
B54: CASH I vitit paraardhes | O54: 0 | P54: 0 | Q54: =+P54 -> 0 | R54: =+Q56 -> 600000 | S54: =+R56 -> 1200000 | T54: =+S56 -> 1750000 | U54: =+T56 -> 2150000 | V54: =+U56 -> 650000 | W54: =+V56 -> 611696 | X54: =+W56 -> 1011696 | Y54: =+X56 -> 1151696 | Z54: 0 | AA54: =+Z56 -> 806319 | AB54: =+AA56 -> 806319 | AD54: 0
B55: Shtesa /pakesime gjate vitit | Q55: 600000 | R55: 600000 | S55: 550000 | T55: 400000 | U55: =-2000000+500000 -> -1500000 | V55: =-838304+800000 -> -38304 | W55: 400000 | X55: 140000 | Z55: =400000+2900*KK!X4 -> 806319 | AB55: 56000
B56: Gjendja e CASH ne analize | Q56: =SUM(Q54:Q55) -> 600000 | R56: =SUM(R54:R55) -> 1200000 | S56: =SUM(S54:S55) -> 1750000 | T56: =SUM(T54:T55) -> 2150000 | U56: =SUM(U54:U55) -> 650000 | V56: =SUM(V54:V55) -> 611696 | W56: =SUM(W54:W55) -> 1011696 | X56: =SUM(X54:X55) -> 1151696 | ... Z56: =SUM(Z54:Z55) -> 806319 | AA56: =+AA54+AA55 -> 806319 | AB56: =SUM(AB54:AB55) -> 862319 | AD56: 0
B57: TOTALI Likujditete | I57: =SUM(I53:I54) -> 0 | J57: =SUM(J53:J54) -> 0 | K57: =SUM(K53:K54) -> 0 | L57: =SUM(L53:L54) -> 0 | M57: =SUM(M53:M54) -> 0 | N57: =SUM(N53:N54) -> 0 | O57: =SUM(O53:O54) -> 0 | P57: =SUM(P53:P54) -> 0 | Q57: =+Q53+Q56 -> 604815.44 | R57: =+R53+R56 -> 1468393.5 | S57: =+S53+S56 -> 1807500 | T57: =+T53+T56 -> 2202998.1 | U57: =+U53+U56 -> 659095.6 | V57: =+V53+V56 -> 660366.04 | W57: =+W53+W56 -> 1073923.1 | X57: =+X53+X56 -> 1212850.1 | ... AD57: =+AD53+AD56 -> 1287604.9
B58: Ndryshim Likujditeti | I58: =+I57 -> 0 | J58: =+J57-I57 -> 0 | K58: =+K57-J57 -> 0 | L58: =+L57-K57 -> 0 | M58: =+M57-L57 -> 0 | N58: =+N57-M57 -> 0 | O58: =+O57-N57 -> 0 | P58: =+P57-O57 -> 0 | Q58: =+Q57-P57 -> 604815.44 | ... AB58: =+AB57-AA57 -> 666773.15 | AD58: =+AD53-AB53-AB55 -> 9673
V60: =U56+800000-838304 -> 611696 | W60: =V60+W55 -> 1011696 | X60: =W60+140000 -> 1151696
Q61: =Q55+Q24+Q10 -> 604815.44 | R61: =R55+Q55+R24+R10 -> 1468393.5 | S61: =S55+R55+Q55+S24+S10 -> 1807500 | T61: =T55+S55+R55+Q55+T24+T10 -> 2202998.1
Q63: =Q61-E61 -> 604815.44 | R63: =R61-Q61 -> 863578.06 | S63: =S61-R61 -> 339106.54 | T63: =T61-S61 -> 395498.02
Q65: =Q53 -> 4815.44 | R65: =R53 -> 268393.5 | S65: =S53 -> 57500.04 | T65: =T53 -> 52998.06 | U65: =U53 -> 9095.6 | V65: =V53 -> 48670.04 | W65: =W53 -> 62227.06 | X65: =X53 -> 61154.06 | ... AB65: =AB53 -> 1221931.9
Q66: =Q55 -> 600000 | R66: =Q66+600000 -> 1200000 | S66: =S55+R66 -> 1750000 | T66: =T55+S66 -> 2150000 | U66: =500000+T66-2000000 -> 650000 | V66: =U66+800000-838304 -> 611696 | W66: =V66+400000 -> 1011696 | X66: =W66+140000 -> 1151696 | Y66: =X66 -> 1151696 | Z66: =400000+2900*KK!X4 -> 806319 | AA66: =Z66 -> 806319 | AB66: =AA66+58000 -> 864319
Q67: =SUM(Q65:Q66) -> 604815.44 | R67: =SUM(R65:R66) -> 1468393.5 | S67: =SUM(S65:S66) -> 1807500 | T67: =SUM(T65:T66) -> 2202998.1 | U67: =SUM(U65:U66) -> 659095.6 | V67: =SUM(V65:V66) -> 660366.04 | W67: =SUM(W65:W66) -> 1073923.1 | X67: =SUM(X65:X66) -> 1212850.1 | ... AB67: =SUM(AB65:AB66) -> 2086250.9
Q68: =Q67-P67 -> 604815.44 | R68: =R67-Q67 -> 863578.06 | S68: =S67-R67 -> 339106.54 | T68: =T67-S67 -> 395498.02 | U68: =U67-T67 -> -1543902.5 | V68: =V67-U67 -> 1270.44 | W68: =W67-V67 -> 413557.02 | X68: =X67-W67 -> 138927 | ... AB68: =AB67-AA67 -> 668773.15
X72: 143042
X73: =X72-W53 -> 80814.94
...

Sheet Analiza fin. 2005-2008
G3: (në lekë)
B4: Nr. | C4: PËRSHKRIMI/PERIUDHA | D4: 2005 | E4: 2006 | F4: 2007 | G4: 2008
B6: I | C6: TË ARDHURA | D6: =SUM(D7:D9) -> 1145795 | E6: =SUM(E7:E9) -> 1093156 | F6: =SUM(F7:F9) -> 1029775 | G6: =SUM(G7:G9) -> 1623858
B7: 1 | C7: Të ardh._S.R. | D7: ='Te Ardhurat '!M5 -> 818245 | E7: ='Te Ardhurat '!N5 -> 815652 | F7: ='Te Ardhurat '!O5+'Te Ardhurat '!O6 -> 841418 | G7: ='Te Ardhurat '!P6 -> 905278
B8: 2 | C8: Të ardh._B.S.R. | D8: ='Te Ardhurat '!M20 -> 327550 | E8: ='Te Ardhurat '!N20 -> 277504 | F8: ='Te Ardhurat '!O22+'Te Ardhurat '!O24 -> 188357 | G8: ='Te Ardhurat '!P22+'Te Ardhurat '!P24 -> 318580
B9: 4 | C9: Shitja_"M.Benz"_ më 09.09.2008 | D9: 0 | E9: 0 | F9: 0 | G9: 400000
B11: II | C11: SHPENZIME | D11: =SUM(D12:D14) -> 438228 | E11: =SUM(E12:E14) -> 438228 | F11: =SUM(F12:F14) -> 547212 | G11: =SUM(G12:G16) -> 767489.44
B12: 1 | C12: Shpenz.jetike | D12: =KK!O14 -> 438228 | E12: =KK!P14 -> 438228 | F12: =KK!Q14 -> 546480 | G12: =KK!R14 -> 546480
B13: 2 | C13: Shpenz.udhët. | D13: 0 | E13: 0 | F13: 0 | G13: =TIMS!C6 -> 3695.475
B14: 3 | C14: Taksat vend._tokës bujq. | D14: 0 | E14: 0 | F14: =2196/3 -> 732 | G14: =F14 -> 732 | I14: 2196
B15: 4 | C15: Paguar int.kredie_NBG Albania ShA | D15: 0 | E15: 0 | F15: 0 | G15: =1726.53*KK!R4 -> 212678.28
B16: 5 | C16: Komisione për transferimin e vlerës | D16: 0 | E16: 0 | F16: 0 | G16: =32*121.99 -> 3903.68
B18: III | C18: PASURI | D18: =SUM(D19:D21) -> 604815.44 | E18: =SUM(E19:E21) -> 863578.06 | F18: =SUM(F19:F21) -> 339106.54 | G18: =SUM(G19:G21) -> 12641685
B19: 1 | C19: Ap.banimi_128.1 m2_23.06.2008 | D19: 0 | E19: 0 | F19: 0 | G19: =94830*121.99 -> 11568312 | J19: 121.99 | K19: 23.06.2008
B20: 2 | C20: Autom."Daimler Chrysler"_14.11.2008 | D20: 0 | E20: 0 | F20: 0 | G20: =5500*123.25 -> 677875 | I20: euro | J20: 123.25 | K20: 14.11.2008
B21: 3 | C21: Ndrysh.gjendje lik. | D21: =' Likujditete'!Q63 -> 604815.44 | E21: =' Likujditete'!R63 -> 863578.06 | F21: =' Likujditete'!S63 -> 339106.54 | G21: =' Likujditete'!T63 -> 395498.02
B23: IV | C23: DETYRIME | D23: =SUM(D24:D25) -> 0 | E23: =SUM(E24:E25) -> 0 | F23: =SUM(F24:F25) -> 0 | G23: =SUM(G24:G26) -> 11479548
B24: 1 | C24: Det.mbetur ndaj shoq,"KDK" ShPk | D24: 0 | E24: 0 | F24: 0 | G24: =48830*121.99 -> 5956771.7
B25: 2 | C25: Kredi bankare_NBG ShA | D25: 0 | E25: 0 | F25: 0 | G25: =46000*121.67 -> 5596820 | J25: 121.67 | K25: 01.08.2008 | M25: 48830
B26: 3 | C26: Shlyer princ.kredie në NBG Albania | D26: 0 | E26: 0 | F26: 0 | G26: =-601.09*KK!R4 -> -74043.769
M27: 46000
B28: V | C28: PASURI NETO: V = III-IV | D28: =D18-(D23) -> 604815.44 | E28: =E18-(E23) -> 863578.06 | F28: =F18-(F23) -> 339106.54 | G28: =G18-(G23) -> 1162136.8 | M28: =SUM(M25:M27) -> 94830
M29: =M28-M27 -> 48830
B30: VI | C30: REZULTATI FIN. VI = I-II-V | D30: =D6-D11-D28 -> 102751.56 | E30: =E6-E11-E28 -> -208650.06 | F30: =F6-F11-F28 -> 143456.46 | G30: =G6-G11-G28 -> -305768.23
H32: =E30+G30 -> -514418.29

Sheet Anal.fin.shly.pjes.
D2: =KK!T14 -> 546480 | E2: =KK!U14 -> 546480 | G2: =KK!V14 -> 558192 | H2: =KK!X14 -> 879992
D4: =D5/30 -> 1518 | E4: =E5/30 -> 1518 | H4: =H5/30 -> 2444.4222
D5: =D2/12 -> 45540 | E5: =E2/12 -> 45540 | G5: =G2/12*7.5 -> 348870 | H5: =H2/12 -> 73332.667
C7: 31.12.2009 | D7: 25.11.2010 | E7: 01.08.2011 | F7: 30.12.2011 | G7: 13.08.2012 | H7: 07.11.2014
A8: A.Sharra | B8: RZB | D8: =1079.55 -> 1079.55 | E8: 35819.65 | F8: =[2]sp_NRP_Balance!$L$533 -> 308.06 | G8: =[2]sp_NRP_Balance!$L$561 -> 225.03 | H8: 60641.78
A9: F.Sharra | B9: TB | D9: 12067 | E9: 47671 | F9: 61919 | G9: =[3]Sheet1!$W$112 -> 242026.88 | H9: 342797
C10: =' Likujditete'!U53 -> 9095.6 | D10: =SUM(D8:D9) -> 13146.55 | E10: =SUM(E8:E9) -> 83490.65 | F10: =SUM(F8:F9) -> 62227.06 | G10: =SUM(G8:G9) -> 242251.91 | H10: =SUM(H8:H9) -> 403438.78 | I10: =' Likujditete'!Y53 -> 3017.83 | J10: =H10-I10 -> 400420.95
D11: =D10-C10 -> 4050.95
D13: 3405 | E13: 3290 | F13: 2060 | G13: 3090 | H13: 15550
B14: Nr. | C14: PERIUDHA | D14: 01.01.– 25.11.2010 | E14: 01.01.- 01.08.2011 | F14: 02.08.-30.12.2011 | G14: 01.01.-13.08.2012 | H14: 01.01.-07.11.2014
D15: I | E15: II | F15: III | G15: IV | H15: V
B16: I | C16: TË ARDHURA | D16: =SUM(D17:D18) -> 1207450 | E16: =SUM(E17:E18) -> 843899 | F16: =SUM(F17:F18) -> 663371 | G16: =SUM(G17:G18) -> 1024913 | H16: =SUM(H17:H19) -> 1664298
B17: 1 | C17: Paga_S.R. | D17: =737467 -> 737467 | E17: =517465 -> 517465 | F17: 411026 | G17: =693828 -> 693828 | H17: 1058086
B18: 2 | C18: Paga_B.S.R. | D18: 469983 | E18: =[4]Sheet1!$AG$19 -> 326434 | F18: =252345 -> 252345 | G18: 331085 | H18: =53229*3+55728*3+45000+55728*2+60228+62657 -> 606212
B19: 3 | C19: Paradh.shitja e ban.K.K. | D19: 0 | E19: 0 | F19: 0 | G19: 0 | H19: 0 | J19: 01.10.2014 | K19: 139.87
B21: II | C21: SHPENZIME | D21: =SUM(D22:D25) -> 717617.76 | E21: =SUM(E22:E25) -> 802927.85 | F21: =SUM(F22:F25) -> 315888.91 | G21: =SUM(G22:G25) -> 454917.48 | H21: =SUM(H22:H25) -> 882827.56 | N21: 45968
B22: 1 | C22: Shenz.jetike | D22: =45540*10+25*1518 -> 493350 | E22: =E5*7+E4 -> 320298 | F22: =E2-E22 -> 226182 | G22: =G2/12*7.5 -> 348870 | H22: =H5*10+7*H4 -> 750437.62 | N22: 5000
B23: 2 | C23: Shpenz.udh. | D23: 0 | E23: =TIMS!F6 -> 338835 | F23: 0 | G23: 0 | H23: 0 | N23: 285 | P23: 31.5.2013
B24: 3 | C24: Int.kredie | D24: ='Kredi ne NBG '!H50*KK!T4 -> 222917.76 | E24: ='Kredi ne NBG '!J58*KK!U4 -> 142444.85 | F24: ='Kredi ne NBG '!J59*KK!U4 -> 89706.912 | G24: ='Kredi ne NBG '!L58*KK!V4 -> 106047.48 | H24: ='Kredi ne NBG '!P53*KK!X4 -> 132389.94 | N24: 24400
B25: 4 | C25: Taksa toke+ndërt. | D25: =2700/2 -> 1350 | E25: =D25 -> 1350 | F25: 0 | G25: 0 | H25: 0 | N25: 5000 | P25: 140.45
N26: 230
B27: III | C27: PASURI | D27: =SUM(D28:D28) -> 4050.95 | E27: =SUM(E28:E29) -> 34820.61 | F27: =SUM(F28:F29) -> 27406.45 | G27: =SUM(G28:G29) -> 180024.85 | H27: =SUM(H28:H29) -> 400420.95 | N27: =SUM(N21:N26) -> 80883 | P27: 40000
B28: 1 | C28: Ndrysh.gjend.lik.bankë | D28: =D10-C10 -> 4050.95 | E28: =E10-' Likujditete'!V53 -> 34820.61 | F28: =F10-E28 -> 27406.45 | G28: =G10-' Likujditete'!W53 -> 180024.85 | H28: =J10 -> 400420.95 | N28: =80883 -> 80883 | P28: =P27/P25 -> 284.79886
B29: 2 | C29: Kursime dekl. | D29: 0 | E29: 0 | F29: 0 | G29: 0 | N29: =N27-N28 -> 0
B31: IV | C31: DETYRIME | D31: =D32 -> -96792.213 | E31: =E32 -> -62696.922 | F31: =F32 -> -752925.95 | G31: =G32 -> -54676.628 | H31: =H32 -> -76707.423
B32: 1 | C32: Princ.kredie NBG | D32: =-'Kredi ne NBG '!G50*KK!T4 -> -96792.213 | E32: =-'Kredi ne NBG '!I58*KK!U4 -> -62696.922 | F32: =-'Kredi ne NBG '!I59*KK!U4 -> -752925.95 | G32: =-'Kredi ne NBG '!K58*KK!V4 -> -54676.628 | H32: =-'Kredi ne NBG '!O53*KK!X4 -> -76707.423
B34: V | C34: PASURI NETO | D34: =D27-(D31) -> 100843.16 | E34: =E27-(E31) -> 97517.532 | F34: =F27-(F31) -> 780332.4 | G34: =G27-(G31) -> 234701.48 | H34: =H27-(H31) -> 477128.37
B36: VI | C36: REZ.FIN: VI=I-II-V | D36: =D16-D21-D34 -> 388989.08 | E36: =E16-E21-E34 -> -56546.383 | F36: =F16-F21-F34 -> -432850.31 | G36: =G16-G21-G34 -> 335294.04 | H36: =H16-H21-H34 -> 304342.07
C37: REZ: (në euro) | D37: =D36/KK!T4 -> 2802.3131 | E37: =E36/KK!U4 -> -408.86756 | F37: =F36/KK!U4 -> -3129.7925 | G37: =G36/KK!V4 -> 2399.757 | H37: =H36/KK!X4 -> 2172.1652
C38: Pagesat e pjes. | D38: =D13 -> 3405 | E38: =E13 -> 3290 | F38: =F13 -> 2060 | G38: =G13 -> 3090 | H38: =H13 -> 15550
D39: =D37-D38 -> -602.6869 | G39: =G37-G38 -> -690.24304 | H39: =H37-H38 -> -13377.835
C41: pa konsideruar paradhënien 20.000 euro, nga shitja e banesës në Kodër Kamëz | H41: 20000
C42: pa konsid të ardhura nga shitja e produkteve bujqësore, me arsyetimin në vijim të relacionit | H42: ok justifikon
C43: pa konsideruar pjesën e kursimeve cash deklaruar në deklaratat periodike të viteve përkatëse e cila mund të
C44: përllogaritej proporcionalisht deri në fund të periudhës së analizuar.
D46: 138.61 | E46: 139.5 | F46: =KK!U4 -> 138.3 | G46: 136.8 | H46: 139.16
D47: =D36/D46 -> 2806.3566 | E47: =E36/E46 -> -405.35042 | F47: =F36/F46 -> -3129.7925 | G47: =G36/G46 -> 2450.9798 | H47: =H36/H46 -> 2186.9939
D49: =D47-D38 -> -598.64345 | E49: =E47-E38 -> -3695.3504 | F49: =F47-F38 -> -5189.7925 | G49: =G47-G38 -> -639.02016 | H49: =H47-H38 -> -13363.006
D50: =D49*D46 -> -82977.968 | E50: =E49*E46 -> -515501.38 | F50: =F49*F46 -> -717748.31 | G50: =G49*G46 -> -87417.958 | H50: =H49*H46 -> -1859595.9
H51: 20000
...

Sheet Te Ardhurat 
B3: Subjekti deklaron ne DV | C3: Dokumentuar ILDKPI | D3: 1996 | E3: 1997 | F3: 1998 | G3: 1999 | H3: 2000 | I3: 2001 | J3: 2002 | K3: 2003 | L3: 2004 | M3: 2005 | N3: 2006 | O3: 2007 | P3: 2008 | Q3: 2009 | R3: 2010 | S3: 2011 | T3: 2012 | U3: 2013 | V3: 2014 | W3: 2015 | X3: 2016 | Y3: Total | Z3: DV 2017 | AA3: 2017 | AB3: 2018 | AC3: 2019
B4: Page OPGJ Gjykata e shkalles se pare Elbasan 01.10.1996-15.07.2004 3,064,193 leke | C4: Vertetim Nr 734 Prot 25.01.2017 nga Gjykata e shkalles se pare ELBASAN | D4: 60154 | E4: 231024 | F4: 360525 | G4: 390615 | H4: 442564 | I4: 446705 | J4: 414633 | K4: 473716 | L4: 244530 | Y4: =SUM(D4:X4) -> 3064466
B5: Page Prokuror ne Gjykaten e shkalles se pare Tirane 16.07.2004-30.04.2007 2,284,783 leke | C5: Vertetim dt 17.10.2016 ngaProkuroria ne Gjykaten e shkalles se pare Tirane | L5: 361664 | M5: 818245 | N5: 815652 | O5: 289222 | Y5: =SUM(D5:X5) -> 2284783
B6: Page Prokuror ne Gjykaten e shkalles se pare Diber 01.05.2007-07.10.2010 2,924,660 leke | C6: Vertetim nga Prokuroria ne Gjykaten e shkalles se pare Diber | O6: 552196 | P6: 905278 | Q6: 851469 | R6: 615717 | Y6: =SUM(D6:X6) -> 2924660
B7: Page Prokuror ne Gjykaten e shkalles se pare Durres Tetor 2010- 31.12.2016 6,428,353 leke | C7: Vertetim nga Prokuroria ne Gjykaten e shkalles se pare Durres dt 11.01.2017 | R7: 198569 | S7: 942368 | T7: 983776 | U7: 917794 | V7: 1091512 | W7: 1123493 | X7: 1170841 | Y7: =SUM(D7:X7) -> 6428353
B8: Page Prokuror ne Gjykaten e shkalles se pare Durres te ardhurat vjetore per 2017 shuma 1,264,368 leke per 2018 shuma 1,227,031 leke per 2019 shuma 2,481,785 leke | C8: Vertetim nga Prokuroria ne Gjykaten e shkalles se pare Durres dt 09.03.2018 | Z8: =+' Likujditete'!AD11 -> 99845 | AA8: 1264368 | AB8: 1227031 | AC8: 2481785
B9: Total | D9: =SUM(D4:D7) -> 60154 | E9: =SUM(E4:E7) -> 231024 | F9: =SUM(F4:F7) -> 360525 | G9: =SUM(G4:G7) -> 390615 | H9: =SUM(H4:H7) -> 442564 | I9: =SUM(I4:I7) -> 446705 | J9: =SUM(J4:J7) -> 414633 | K9: =SUM(K4:K7) -> 473716 | ... U9: =SUM(U4:U7) -> 917794 | V9: =SUM(V4:V8) -> 1091512 | W9: =SUM(W4:W8) -> 1123493 | X9: =SUM(X4:X8) -> 1170841 | Y9: =SUM(Y4:Y8) -> 14702262 | Z9: =SUM(Z4:Z8) -> 99845 | AA9: =SUM(AA4:AA8) -> 1264368 | AB9: =SUM(AB4:AB8) -> 1227031 | AC9: =SUM(AC4:AC8) -> 2481785
B11: Paga te kaluara ne Banke | M11: =+' Likujditete'!Q11 -> 648255 | N11: =+' Likujditete'!R11 -> 835937 | O11: =+' Likujditete'!S11 -> 912971 | P11: =+' Likujditete'!T11 -> 888580 | Q11: =+' Likujditete'!U11 -> 808684 | R11: =+' Likujditete'!V11 -> 829725 | S11: =+' Likujditete'!W11 -> 928491 | T11: =+' Likujditete'!X11 -> 994162 | ... X11: =+' Likujditete'!AB11 -> 1164829 | Z11: =+' Likujditete'!AD11 -> 99845 | AA11: =+' Likujditete'!#REF! -> #REF! | AB11: =+' Likujditete'!#REF! -> #REF! | AC11: =+' Likujditete'!#REF! -> #REF!
B18: Te ardhurat e b/shortes se subjektit | C18: Dokumentuar ILDKPI | D18: 1996 | E18: 1997 | F18: 1998 | G18: 1999 | H18: 2000 | I18: 2001 | J18: 2002 | K18: 2003 | L18: 2004 | M18: 2005 | N18: 2006 | O18: 2007 | P18: 2008 | Q18: 2009 | R18: 2010 | S18: 2011 | T18: 2012 | U18: 2013 | V18: 2014 | W18: 2015 | X18: 2016 | Y18: Total | Z18: DV 2017 | AA18: 2017 | AB18: 2018 | AC18: 2019
B19: Barre lindje per djalin 01.07.1997-12.06.1998 e padokumentuar per shkak te mos gjetjes se dokumentacionit ne DRSSHT | E19: xxx | F19: xxx | Y19: =SUM(D19:X19) -> 0
B20: Page juriste Ndermarrja e trajtimit te studenteve nr ! Tirane Maj 1999-Shtator 2006 1,765,318 Leke | C20: Vertetim nga ISSH mbi bazen e vleresueshme dhe pagen neto mesatare si juriste ne shoqerine Rezidenca Studentore Universitare nr 1 sha Tirane | G20: 70634 | H20: 160873 | I20: 177089 | J20: 132813 | K20: 291424 | L20: 327431 | M20: 327550 | N20: 277504 | Y20: =SUM(D20:X20) -> 1765318
